<?xml version="1.0" encoding="utf-8"?>
<!-- This URDF was automatically created by SolidWorks to URDF Exporter! Originally created by Stephen Brawner (brawner@gmail.com) 
     Commit Version: 1.6.0-1-g15f4949  Build Version: 1.6.7594.29634
     For more information, please see http://wiki.ros.org/sw_urdf_exporter -->
<robot
  name="endmeplz">
  <link
    name="base_link">
    <inertial>
      <origin
        xyz="0.000631713493736336 -3.02928458977558E-05 0.028430776065193"
        rpy="0 0 0" />
      <mass
        value="3.80330319179046" />
      <inertia
        ixx="0.00452100760029914"
        ixy="-3.16232627333116E-06"
        ixz="3.52203764610653E-06"
        iyy="0.0044975551721144"
        iyz="-1.73828961083293E-06"
        izz="0.00711790515099519" />
    </inertial>
    <visual>
      <origin
        xyz="0 0 0"
        rpy="0 0 0" />
      <geometry>
        <mesh
          filename="package://endmeplz/meshes/base_link.STL" />
      </geometry>
      <material
        name="">
        <color
          rgba="0.792156862745098 0.819607843137255 0.933333333333333 1" />
      </material>
    </visual>
    <collision>
      <origin
        xyz="0 0 0"
        rpy="0 0 0" />
      <geometry>
        <mesh
          filename="package://endmeplz/meshes/base_link.STL" />
      </geometry>
    </collision>
  </link>
  <link
    name="link_1">
    <inertial>
      <origin
        xyz="0.00015379 0.0029928 -0.021081"
        rpy="0 0 0" />
      <mass
        value="0.6359" />
      <inertia
        ixx="0.00018621"
        ixy="-1.0373E-06"
        ixz="1.2097E-08"
        iyy="0.00016446"
        iyz="1.9361E-07"
        izz="0.00029792" />
    </inertial>
    <visual>
      <origin
        xyz="0 0 0"
        rpy="0 0 0" />
      <geometry>
        <mesh
          filename="package://endmeplz/meshes/link_1.STL" />
      </geometry>
      <material
        name="">
        <color
          rgba="0.79216 0.81961 0.93333 1" />
      </material>
    </visual>
    <collision>
      <origin
        xyz="0 0 0"
        rpy="0 0 0" />
      <geometry>
        <mesh
          filename="package://endmeplz/meshes/link_1.STL" />
      </geometry>
    </collision>
  </link>
  <joint
    name="joint_1"
    type="revolute">
    <origin
      xyz="0 0 0.1049"
      rpy="0 0 0" />
    <parent
      link="base_link" />
    <child
      link="link_1" />
    <axis
      xyz="0 0 1" />
    <limit
      lower="-3.1"
      upper="3.1"
      effort="0"
      velocity="0" />
  </joint>
  <link
    name="link_2">
    <inertial>
      <origin
        xyz="1.0481E-07 -5.7272E-10 0.03803"
        rpy="0 0 0" />
      <mass
        value="0.10413" />
      <inertia
        ixx="2.9727E-05"
        ixy="-3.8595E-13"
        ixz="-6.8475E-12"
        iyy="6.3482E-05"
        iyz="6.1154E-12"
        izz="4.7388E-05" />
    </inertial>
    <visual>
      <origin
        xyz="0 0 0"
        rpy="0 0 0" />
      <geometry>
        <mesh
          filename="package://endmeplz/meshes/link_2.STL" />
      </geometry>
      <material
        name="">
        <color
          rgba="0.79216 0.81961 0.93333 1" />
      </material>
    </visual>
    <collision>
      <origin
        xyz="0 0 0"
        rpy="0 0 0" />
      <geometry>
        <mesh
          filename="package://endmeplz/meshes/link_2.STL" />
      </geometry>
    </collision>
  </link>
  <joint
    name="joint_2"
    type="revolute">
    <origin
      xyz="0 0.017906 -0.01425"
      rpy="0.78645 0 0" />
    <parent
      link="link_1" />
    <child
      link="link_2" />
    <axis
      xyz="1 0 0" />
    <limit
      lower="-2.3"
      upper="0"
      effort="0"
      velocity="0" />
  </joint>
  <link
    name="link_3">
    <inertial>
      <origin
        xyz="0.00026088 -4.1471E-11 0.03875"
        rpy="0 0 0" />
      <mass
        value="0.86322" />
      <inertia
        ixx="0.00025078"
        ixy="8.0452E-14"
        ixz="-1.1558E-11"
        iyy="0.00030268"
        iyz="-1.2921E-10"
        izz="0.00015129" />
    </inertial>
    <visual>
      <origin
        xyz="0 0 0"
        rpy="0 0 0" />
      <geometry>
        <mesh
          filename="package://endmeplz/meshes/link_3.STL" />
      </geometry>
      <material
        name="">
        <color
          rgba="0.79216 0.81961 0.93333 1" />
      </material>
    </visual>
    <collision>
      <origin
        xyz="0 0 0"
        rpy="0 0 0" />
      <geometry>
        <mesh
          filename="package://endmeplz/meshes/link_3.STL" />
      </geometry>
    </collision>
  </link>
  <joint
    name="joint_3"
    type="revolute">
    <origin
      xyz="0 0 0.07606"
      rpy="-1.5708 0 0" />
    <parent
      link="link_2" />
    <child
      link="link_3" />
    <axis
      xyz="-1 0 0" />
    <limit
      lower="-2.35"
      upper="0.7"
      effort="0"
      velocity="0" />
  </joint>
  <link
    name="link_4">
    <inertial>
      <origin
        xyz="0.00060001 0.056626 -0.010172"
        rpy="0 0 0" />
      <mass
        value="0.4503" />
      <inertia
        ixx="0.00012715"
        ixy="-6.9826E-11"
        ixz="-8.6987E-12"
        iyy="0.00012052"
        iyz="-3.7464E-07"
        izz="0.00010698" />
    </inertial>
    <visual>
      <origin
        xyz="0 0 0"
        rpy="0 0 0" />
      <geometry>
        <mesh
          filename="package://endmeplz/meshes/link_4.STL" />
      </geometry>
      <material
        name="">
        <color
          rgba="0.79216 0.81961 0.93333 1" />
      </material>
    </visual>
    <collision>
      <origin
        xyz="0 0 0"
        rpy="0 0 0" />
      <geometry>
        <mesh
          filename="package://endmeplz/meshes/link_4.STL" />
      </geometry>
    </collision>
  </link>
  <joint
    name="joint_4"
    type="revolute">
    <origin
      xyz="0 0 0.0775"
      rpy="0.78435 0 0" />
    <parent
      link="link_3" />
    <child
      link="link_4" />
    <axis
      xyz="1 0 0" />
    <limit
      lower="-0.5"
      upper="2.5"
      effort="0"
      velocity="0" />
  </joint>
  <link
    name="link_5">
    <inertial>
      <origin
        xyz="-0.00034131 0.078598 -0.009587"
        rpy="0 0 0" />
      <mass
        value="1.0138" />
      <inertia
        ixx="0.00028883"
        ixy="4.4009E-07"
        ixz="-6.3691E-07"
        iyy="0.00024565"
        iyz="5.5079E-06"
        izz="0.00040237" />
    </inertial>
    <visual>
      <origin
        xyz="0 0 0"
        rpy="0 0 0" />
      <geometry>
        <mesh
          filename="package://endmeplz/meshes/link_5.STL" />
      </geometry>
      <material
        name="">
        <color
          rgba="0.79216 0.81961 0.93333 1" />
      </material>
    </visual>
    <collision>
      <origin
        xyz="0 0 0"
        rpy="0 0 0" />
      <geometry>
        <mesh
          filename="package://endmeplz/meshes/link_5.STL" />
      </geometry>
    </collision>
  </link>
  <joint
    name="joint_5"
    type="revolute">
    <origin
      xyz="0.0016851 0.038575 -0.024092"
      rpy="0 0 0" />
    <parent
      link="link_4" />
    <child
      link="link_5" />
    <axis
      xyz="0 -1 0" />
    <limit
      lower="-1.4"
      upper="1.4"
      effort="0"
      velocity="0" />
  </joint>
</robot>
